Workbook

Sheet RESUMEN
A1: Última actualización: | B1: =TODAY() -> 46049
A2: Categoría | B2: Total | C2: Tengo | D2: Faltan | E2: Progreso | F2: Progreso VISUAL
A3: REGULARES | B3: 360 | C3: =COUNTIF(REGULARES!D:D, "SI") -> 197 | D3: =B3-C3 -> 163 | E3: =(C3/B3) -> 0.54722222 | F3: =IFERROR(__xludf.DUMMYFUNCTION("SPARKLINE(E3, {""charttype"",""bar""; ""max"",1; ""color1"",""green""; ""empty"",""ignore""})"),"")
A4: ESTADIOS | B4: 20 | C4: =COUNTIF(Estadios!D:D, "SI") -> 14 | D4: =B4-C4 -> 6 | E4: =(C4/B4) -> 0.7
A5: VAMOS | B5: 20 | C5: =COUNTIF('¡VAMOS! (361–380)'!D:D, "SI") -> 8 | D5: =B5-C5 -> 12 | E5: =C5/B5 -> 0.4 | F5: =IFERROR(__xludf.DUMMYFUNCTION("SPARKLINE(E5, {""charttype"",""bar""; ""max"",1; ""color1"",""green""; ""empty"",""ignore""})"),"")
A6: Guantes de Oro | B6: 7 | C6: =COUNTIF('Guantes de Oro (381–387)'!D:D, "SI") -> 2 | D6: =B6-C6 -> 5 | E6: =C6/B6 -> 0.28571429 | F6: =IFERROR(__xludf.DUMMYFUNCTION("SPARKLINE(E6, {""charttype"",""bar""; ""max"",1; ""color1"",""green""; ""empty"",""ignore""})"),"")
A7: Kryptonita | B7: 9 | C7: =COUNTIF('Kryptonita (388–396)'!D:D, "SI") -> 3 | D7: =B7-C7 -> 6 | E7: =C7/B7 -> 0.33333333 | F7: =IFERROR(__xludf.DUMMYFUNCTION("SPARKLINE(E7, {""charttype"",""bar""; ""max"",1; ""color1"",""green""; ""empty"",""ignore""})"),"")
A8: Diamantes | B8: 18 | C8: =COUNTIF('Diamantes (397–414)'!D:D, "SI") -> 12 | D8: =B8-C8 -> 6 | E8: =C8/B8 -> 0.66666667 | F8: =IFERROR(__xludf.DUMMYFUNCTION("SPARKLINE(E8, {""charttype"",""bar""; ""max"",1; ""color1"",""green""; ""empty"",""ignore""})"),"")
A9: Influencers | B9: 9 | C9: =COUNTIF('Influencers (415–423)'!D:D, "SI") -> 5 | D9: =B9-C9 -> 4 | E9: =C9/B9 -> 0.55555556 | F9: =IFERROR(__xludf.DUMMYFUNCTION("SPARKLINE(E9, {""charttype"",""bar""; ""max"",1; ""color1"",""green""; ""empty"",""ignore""})"),"")
A10: Protas | B10: 18 | C10: =COUNTIF('Protas (424–441)'!D:D, "SI") -> 8 | D10: =B10-C10 -> 10 | E10: =C10/B10 -> 0.44444444 | F10: =IFERROR(__xludf.DUMMYFUNCTION("SPARKLINE(E10, {""charttype"",""bar""; ""max"",1; ""color1"",""green""; ""empty"",""ignore""})"),"")
A11: Super Cracks | B11: 26 | C11: =COUNTIF('Super Cracks (442–467)'!D:D, "SI") -> 12 | D11: =B11-C11 -> 14 | E11: =C11/B11 -> 0.46153846 | F11: =IFERROR(__xludf.DUMMYFUNCTION("SPARKLINE(E11, {""charttype"",""bar""; ""max"",1; ""color1"",""green""; ""empty"",""ignore""})"),"")
A12: CARTAS TOP | B12: 11 | C12: =COUNTIF('Cartas Top y Únicas (468–478)'!D:D, "SI") -> 3 | D12: =B12-C12 -> 8 | E12: =C12/B12 -> 0.27272727 | F12: =IFERROR(__xludf.DUMMYFUNCTION("SPARKLINE(E12, {""charttype"",""bar""; ""max"",1; ""color1"",""green""; ""empty"",""ignore""})"),"")
A13: TOTAL COLECCIÓN | B13: =SUM(B3:B12) -> 498 | C13: =SUM(C3:C12) -> 264 | D13: =SUM(D3:D12) -> 234 | E13: =C13/B13 -> 0.53012048 | F13: =IFERROR(__xludf.DUMMYFUNCTION("SPARKLINE(E13, {""charttype"",""bar""; ""max"",1; ""color1"",""green""; ""empty"",""ignore""})"),"")

Sheet LO QUE ME FALTA
A1: =IFERROR(__xludf.DUMMYFUNCTION("{FILTER(REGULARES!A:C, REGULARES!D:D<>""SI"", REGULARES!A:A<>""""); FILTER('¡VAMOS! (361–380)'!A:C, '¡VAMOS! (361–380)'!D:D<>""SI"", '¡VAMOS! (361–380)'!A:A<>""""); FILTER('Guantes de Oro (381–387)'!A:C, 'Guantes de Oro (381–387)'!D:D<>""SI"", 'Guantes de"&" Oro (381–387)'!A:A<>""""); FILTER('Kryptonita (388–396)'!A:C, 'Kryptonita (388–396)'!D:D<>""SI"", 'Kryptonita (388–396)'!A:A<>""""); FILTER('Diamantes (397–414)'!A:C, 'Diamantes (397–414)'!D:D<>""SI"", 'Diamantes (397–414)'!A:A<>""""); FILTER('Influencer"&"s (415–423)'!A:C, 'Influencers (415–423)'!D:D<>""SI"", 'Influencers (415–423)'!A:A<>""""); FILTER('Protas (424–441)'!A:C, 'Protas (424–441)'!D:D<>""SI"", 'Protas (424–441)'!A:A<>""""); FILTER('Super Cracks (442–467)'!A:C, 'Super Cracks (442–467)'!D:D<>""S"&"I"", 'Super Cracks (442–467)'!A:A<>""""); FILTER('Cartas Top y Únicas (468–478)'!A:C, 'Cartas Top y Únicas (468–478)'!D:D<>""SI"", 'Cartas Top y Únicas (468–478)'!A:A<>""""); FILTER(Estadios!A:C, Estadios!D:D<>""SI"", Estadios!A:A<>"""")}"),2.0) -> 2 | B1: =IFERROR(__xludf.DUMMYFUNCTION("""COMPUTED_VALUE"""),"SIVERA") -> SIVERA | C1: =IFERROR(__xludf.DUMMYFUNCTION("""COMPUTED_VALUE"""),"D. ALAVÉS") -> D. ALAVÉS
A2: =IFERROR(__xludf.DUMMYFUNCTION("""COMPUTED_VALUE"""),5.0) -> 5 | B2: =IFERROR(__xludf.DUMMYFUNCTION("""COMPUTED_VALUE"""),"TENAGLIA") -> TENAGLIA | C2: =IFERROR(__xludf.DUMMYFUNCTION("""COMPUTED_VALUE"""),"D. ALAVÉS") -> D. ALAVÉS
A3: =IFERROR(__xludf.DUMMYFUNCTION("""COMPUTED_VALUE"""),8.0) -> 8 | B3: =IFERROR(__xludf.DUMMYFUNCTION("""COMPUTED_VALUE"""),"MOUSSA DIARRA") -> MOUSSA DIARRA | C3: =IFERROR(__xludf.DUMMYFUNCTION("""COMPUTED_VALUE"""),"D. ALAVÉS") -> D. ALAVÉS
A4: =IFERROR(__xludf.DUMMYFUNCTION("""COMPUTED_VALUE"""),11.0) -> 11 | B4: =IFERROR(__xludf.DUMMYFUNCTION("""COMPUTED_VALUE"""),"GURIDI") -> GURIDI | C4: =IFERROR(__xludf.DUMMYFUNCTION("""COMPUTED_VALUE"""),"D. ALAVÉS") -> D. ALAVÉS
A5: =IFERROR(__xludf.DUMMYFUNCTION("""COMPUTED_VALUE"""),12.0) -> 12 | B5: =IFERROR(__xludf.DUMMYFUNCTION("""COMPUTED_VALUE"""),"ALEÑÁ") -> ALEÑÁ | C5: =IFERROR(__xludf.DUMMYFUNCTION("""COMPUTED_VALUE"""),"D. ALAVÉS") -> D. ALAVÉS
A6: =IFERROR(__xludf.DUMMYFUNCTION("""COMPUTED_VALUE"""),13.0) -> 13 | B6: =IFERROR(__xludf.DUMMYFUNCTION("""COMPUTED_VALUE"""),"PABLO IBÁÑEZ") -> PABLO IBÁÑEZ | C6: =IFERROR(__xludf.DUMMYFUNCTION("""COMPUTED_VALUE"""),"D. ALAVÉS") -> D. ALAVÉS
A7: =IFERROR(__xludf.DUMMYFUNCTION("""COMPUTED_VALUE"""),14.0) -> 14 | B7: =IFERROR(__xludf.DUMMYFUNCTION("""COMPUTED_VALUE"""),"DENIS SUÁREZ") -> DENIS SUÁREZ | C7: =IFERROR(__xludf.DUMMYFUNCTION("""COMPUTED_VALUE"""),"D. ALAVÉS") -> D. ALAVÉS
A8: =IFERROR(__xludf.DUMMYFUNCTION("""COMPUTED_VALUE"""),16.0) -> 16 | B8: =IFERROR(__xludf.DUMMYFUNCTION("""COMPUTED_VALUE"""),"TONI MARTÍNEZ") -> TONI MARTÍNEZ | C8: =IFERROR(__xludf.DUMMYFUNCTION("""COMPUTED_VALUE"""),"D. ALAVÉS") -> D. ALAVÉS
A9: =IFERROR(__xludf.DUMMYFUNCTION("""COMPUTED_VALUE"""),19.0) -> 19 | B9: =IFERROR(__xludf.DUMMYFUNCTION("""COMPUTED_VALUE"""),"ESCUDO") -> ESCUDO | C9: =IFERROR(__xludf.DUMMYFUNCTION("""COMPUTED_VALUE"""),"ATHLETIC CLUB") -> ATHLETIC CLUB
A10: =IFERROR(__xludf.DUMMYFUNCTION("""COMPUTED_VALUE"""),20.0) -> 20 | B10: =IFERROR(__xludf.DUMMYFUNCTION("""COMPUTED_VALUE"""),"UNAI SIMÓN") -> UNAI SIMÓN | C10: =IFERROR(__xludf.DUMMYFUNCTION("""COMPUTED_VALUE"""),"ATHLETIC CLUB") -> ATHLETIC CLUB
A11: =IFERROR(__xludf.DUMMYFUNCTION("""COMPUTED_VALUE"""),24.0) -> 24 | B11: =IFERROR(__xludf.DUMMYFUNCTION("""COMPUTED_VALUE"""),"PAREDES") -> PAREDES | C11: =IFERROR(__xludf.DUMMYFUNCTION("""COMPUTED_VALUE"""),"ATHLETIC CLUB") -> ATHLETIC CLUB
A12: =IFERROR(__xludf.DUMMYFUNCTION("""COMPUTED_VALUE"""),25.0) -> 25 | B12: =IFERROR(__xludf.DUMMYFUNCTION("""COMPUTED_VALUE"""),"LAPORTE") -> LAPORTE | C12: =IFERROR(__xludf.DUMMYFUNCTION("""COMPUTED_VALUE"""),"ATHLETIC CLUB") -> ATHLETIC CLUB
A13: =IFERROR(__xludf.DUMMYFUNCTION("""COMPUTED_VALUE"""),26.0) -> 26 | B13: =IFERROR(__xludf.DUMMYFUNCTION("""COMPUTED_VALUE"""),"YURI") -> YURI | C13: =IFERROR(__xludf.DUMMYFUNCTION("""COMPUTED_VALUE"""),"ATHLETIC CLUB") -> ATHLETIC CLUB
A14: =IFERROR(__xludf.DUMMYFUNCTION("""COMPUTED_VALUE"""),28.0) -> 28 | B14: =IFERROR(__xludf.DUMMYFUNCTION("""COMPUTED_VALUE"""),"JAUREGIZAR") -> JAUREGIZAR | C14: =IFERROR(__xludf.DUMMYFUNCTION("""COMPUTED_VALUE"""),"ATHLETIC CLUB") -> ATHLETIC CLUB
A15: =IFERROR(__xludf.DUMMYFUNCTION("""COMPUTED_VALUE"""),29.0) -> 29 | B15: =IFERROR(__xludf.DUMMYFUNCTION("""COMPUTED_VALUE"""),"VESGA") -> VESGA | C15: =IFERROR(__xludf.DUMMYFUNCTION("""COMPUTED_VALUE"""),"ATHLETIC CLUB") -> ATHLETIC CLUB
A16: =IFERROR(__xludf.DUMMYFUNCTION("""COMPUTED_VALUE"""),30.0) -> 30 | B16: =IFERROR(__xludf.DUMMYFUNCTION("""COMPUTED_VALUE"""),"UNAI GÓMEZ") -> UNAI GÓMEZ | C16: =IFERROR(__xludf.DUMMYFUNCTION("""COMPUTED_VALUE"""),"ATHLETIC CLUB") -> ATHLETIC CLUB
A17: =IFERROR(__xludf.DUMMYFUNCTION("""COMPUTED_VALUE"""),32.0) -> 32 | B17: =IFERROR(__xludf.DUMMYFUNCTION("""COMPUTED_VALUE"""),"BERENGUER") -> BERENGUER | C17: =IFERROR(__xludf.DUMMYFUNCTION("""COMPUTED_VALUE"""),"ATHLETIC CLUB") -> ATHLETIC CLUB
A18: =IFERROR(__xludf.DUMMYFUNCTION("""COMPUTED_VALUE"""),35.0) -> 35 | B18: =IFERROR(__xludf.DUMMYFUNCTION("""COMPUTED_VALUE"""),"GURUZETA") -> GURUZETA | C18: =IFERROR(__xludf.DUMMYFUNCTION("""COMPUTED_VALUE"""),"ATHLETIC CLUB") -> ATHLETIC CLUB
A19: =IFERROR(__xludf.DUMMYFUNCTION("""COMPUTED_VALUE"""),36.0) -> 36 | B19: =IFERROR(__xludf.DUMMYFUNCTION("""COMPUTED_VALUE"""),"NICO WILLIAMS") -> NICO WILLIAMS | C19: =IFERROR(__xludf.DUMMYFUNCTION("""COMPUTED_VALUE"""),"ATHLETIC CLUB") -> ATHLETIC CLUB
A20: =IFERROR(__xludf.DUMMYFUNCTION("""COMPUTED_VALUE"""),37.0) -> 37 | B20: =IFERROR(__xludf.DUMMYFUNCTION("""COMPUTED_VALUE"""),"ESCUDO") -> ESCUDO | C20: =IFERROR(__xludf.DUMMYFUNCTION("""COMPUTED_VALUE"""),"ATLÉTICO DE MADRID") -> ATLÉTICO DE MADRID
A21: =IFERROR(__xludf.DUMMYFUNCTION("""COMPUTED_VALUE"""),38.0) -> 38 | B21: =IFERROR(__xludf.DUMMYFUNCTION("""COMPUTED_VALUE"""),"OBLAK") -> OBLAK | C21: =IFERROR(__xludf.DUMMYFUNCTION("""COMPUTED_VALUE"""),"ATLÉTICO DE MADRID") -> ATLÉTICO DE MADRID
A22: =IFERROR(__xludf.DUMMYFUNCTION("""COMPUTED_VALUE"""),45.0) -> 45 | B22: =IFERROR(__xludf.DUMMYFUNCTION("""COMPUTED_VALUE"""),"KOKE") -> KOKE | C22: =IFERROR(__xludf.DUMMYFUNCTION("""COMPUTED_VALUE"""),"ATLÉTICO DE MADRID") -> ATLÉTICO DE MADRID
A23: =IFERROR(__xludf.DUMMYFUNCTION("""COMPUTED_VALUE"""),48.0) -> 48 | B23: =IFERROR(__xludf.DUMMYFUNCTION("""COMPUTED_VALUE"""),"ALEX BAENA") -> ALEX BAENA | C23: =IFERROR(__xludf.DUMMYFUNCTION("""COMPUTED_VALUE"""),"ATLÉTICO DE MADRID") -> ATLÉTICO DE MADRID
A24: =IFERROR(__xludf.DUMMYFUNCTION("""COMPUTED_VALUE"""),50.0) -> 50 | B24: =IFERROR(__xludf.DUMMYFUNCTION("""COMPUTED_VALUE"""),"NICO GONZÁLEZ") -> NICO GONZÁLEZ | C24: =IFERROR(__xludf.DUMMYFUNCTION("""COMPUTED_VALUE"""),"ATLÉTICO DE MADRID") -> ATLÉTICO DE MADRID
A25: =IFERROR(__xludf.DUMMYFUNCTION("""COMPUTED_VALUE"""),51.0) -> 51 | B25: =IFERROR(__xludf.DUMMYFUNCTION("""COMPUTED_VALUE"""),"GIULIANO") -> GIULIANO | C25: =IFERROR(__xludf.DUMMYFUNCTION("""COMPUTED_VALUE"""),"ATLÉTICO DE MADRID") -> ATLÉTICO DE MADRID
A26: =IFERROR(__xludf.DUMMYFUNCTION("""COMPUTED_VALUE"""),52.0) -> 52 | B26: =IFERROR(__xludf.DUMMYFUNCTION("""COMPUTED_VALUE"""),"JULIÁN ALVAREZ") -> JULIÁN ALVAREZ | C26: =IFERROR(__xludf.DUMMYFUNCTION("""COMPUTED_VALUE"""),"ATLÉTICO DE MADRID") -> ATLÉTICO DE MADRID
A27: =IFERROR(__xludf.DUMMYFUNCTION("""COMPUTED_VALUE"""),53.0) -> 53 | B27: =IFERROR(__xludf.DUMMYFUNCTION("""COMPUTED_VALUE"""),"SORLOTH") -> SORLOTH | C27: =IFERROR(__xludf.DUMMYFUNCTION("""COMPUTED_VALUE"""),"ATLÉTICO DE MADRID") -> ATLÉTICO DE MADRID
A28: =IFERROR(__xludf.DUMMYFUNCTION("""COMPUTED_VALUE"""),54.0) -> 54 | B28: =IFERROR(__xludf.DUMMYFUNCTION("""COMPUTED_VALUE"""),"GRIEZMANN") -> GRIEZMANN | C28: =IFERROR(__xludf.DUMMYFUNCTION("""COMPUTED_VALUE"""),"ATLÉTICO DE MADRID") -> ATLÉTICO DE MADRID
A29: =IFERROR(__xludf.DUMMYFUNCTION("""COMPUTED_VALUE"""),57.0) -> 57 | B29: =IFERROR(__xludf.DUMMYFUNCTION("""COMPUTED_VALUE"""),"SZCZESNY") -> SZCZESNY | C29: =IFERROR(__xludf.DUMMYFUNCTION("""COMPUTED_VALUE"""),"FC BARCELONA") -> FC BARCELONA
A30: =IFERROR(__xludf.DUMMYFUNCTION("""COMPUTED_VALUE"""),58.0) -> 58 | B30: =IFERROR(__xludf.DUMMYFUNCTION("""COMPUTED_VALUE"""),"KOUNDÉ") -> KOUNDÉ | C30: =IFERROR(__xludf.DUMMYFUNCTION("""COMPUTED_VALUE"""),"FC BARCELONA") -> FC BARCELONA
A31: =IFERROR(__xludf.DUMMYFUNCTION("""COMPUTED_VALUE"""),60.0) -> 60 | B31: =IFERROR(__xludf.DUMMYFUNCTION("""COMPUTED_VALUE"""),"ERIC GARCÍA") -> ERIC GARCÍA | C31: =IFERROR(__xludf.DUMMYFUNCTION("""COMPUTED_VALUE"""),"FC BARCELONA") -> FC BARCELONA
A32: =IFERROR(__xludf.DUMMYFUNCTION("""COMPUTED_VALUE"""),61.0) -> 61 | B32: =IFERROR(__xludf.DUMMYFUNCTION("""COMPUTED_VALUE"""),"ARAÚJO") -> ARAÚJO | C32: =IFERROR(__xludf.DUMMYFUNCTION("""COMPUTED_VALUE"""),"FC BARCELONA") -> FC BARCELONA
A33: =IFERROR(__xludf.DUMMYFUNCTION("""COMPUTED_VALUE"""),66.0) -> 66 | B33: =IFERROR(__xludf.DUMMYFUNCTION("""COMPUTED_VALUE"""),"FERMÍN") -> FERMÍN | C33: =IFERROR(__xludf.DUMMYFUNCTION("""COMPUTED_VALUE"""),"FC BARCELONA") -> FC BARCELONA
A34: =IFERROR(__xludf.DUMMYFUNCTION("""COMPUTED_VALUE"""),68.0) -> 68 | B34: =IFERROR(__xludf.DUMMYFUNCTION("""COMPUTED_VALUE"""),"RAPHINHA") -> RAPHINHA | C34: =IFERROR(__xludf.DUMMYFUNCTION("""COMPUTED_VALUE"""),"FC BARCELONA") -> FC BARCELONA
A35: =IFERROR(__xludf.DUMMYFUNCTION("""COMPUTED_VALUE"""),69.0) -> 69 | B35: =IFERROR(__xludf.DUMMYFUNCTION("""COMPUTED_VALUE"""),"LAMINE YAMAL") -> LAMINE YAMAL | C35: =IFERROR(__xludf.DUMMYFUNCTION("""COMPUTED_VALUE"""),"FC BARCELONA") -> FC BARCELONA
A36: =IFERROR(__xludf.DUMMYFUNCTION("""COMPUTED_VALUE"""),70.0) -> 70 | B36: =IFERROR(__xludf.DUMMYFUNCTION("""COMPUTED_VALUE"""),"FERRAN TORRES") -> FERRAN TORRES | C36: =IFERROR(__xludf.DUMMYFUNCTION("""COMPUTED_VALUE"""),"FC BARCELONA") -> FC BARCELONA
A37: =IFERROR(__xludf.DUMMYFUNCTION("""COMPUTED_VALUE"""),72.0) -> 72 | B37: =IFERROR(__xludf.DUMMYFUNCTION("""COMPUTED_VALUE"""),"RASHFORD") -> RASHFORD | C37: =IFERROR(__xludf.DUMMYFUNCTION("""COMPUTED_VALUE"""),"FC BARCELONA") -> FC BARCELONA
A38: =IFERROR(__xludf.DUMMYFUNCTION("""COMPUTED_VALUE"""),75.0) -> 75 | B38: =IFERROR(__xludf.DUMMYFUNCTION("""COMPUTED_VALUE"""),"VALLES") -> VALLES | C38: =IFERROR(__xludf.DUMMYFUNCTION("""COMPUTED_VALUE"""),"REAL BETIS") -> REAL BETIS
A39: =IFERROR(__xludf.DUMMYFUNCTION("""COMPUTED_VALUE"""),77.0) -> 77 | B39: =IFERROR(__xludf.DUMMYFUNCTION("""COMPUTED_VALUE"""),"BARTRA") -> BARTRA | C39: =IFERROR(__xludf.DUMMYFUNCTION("""COMPUTED_VALUE"""),"REAL BETIS") -> REAL BETIS
A40: =IFERROR(__xludf.DUMMYFUNCTION("""COMPUTED_VALUE"""),78.0) -> 78 | B40: =IFERROR(__xludf.DUMMYFUNCTION("""COMPUTED_VALUE"""),"DIEGO LLORENTE") -> DIEGO LLORENTE | C40: =IFERROR(__xludf.DUMMYFUNCTION("""COMPUTED_VALUE"""),"REAL BETIS") -> REAL BETIS
...

Sheet REPETIDOS
A1: =IFERROR(__xludf.DUMMYFUNCTION("QUERY({ IFERROR(FILTER({REGULARES!A:C, REGULARES!E:E}, REGULARES!E:E>0), {"""","""","""",""""}); IFERROR(FILTER({'¡VAMOS! (361–380)'!A:C, '¡VAMOS! (361–380)'!E:E}, '¡VAMOS! (361–380)'!E:E>0), {"""","""","""",""""}); IFERROR(FILTER({'Guantes de Oro ("&"381–387)'!A:C, 'Guantes de Oro (381–387)'!E:E}, 'Guantes de Oro (381–387)'!E:E>0), {"""","""","""",""""}); IFERROR(FILTER({'Kryptonita (388–396)'!A:C, 'Kryptonita (388–396)'!E:E}, 'Kryptonita (388–396)'!E:E>0), {"""","""","""",""""}); IFERROR(FILTER({"&"'Diamantes (397–414)'!A:C, 'Diamantes (397–414)'!E:E}, 'Diamantes (397–414)'!E:E>0), {"""","""","""",""""}); IFERROR(FILTER({'Influencers (415–423)'!A:C, 'Influencers (415–423)'!E:E}, 'Influencers (415–423)'!E:E>0), {"""","""","""",""""}); IFERROR(FIL"&"TER({'Protas (424–441)'!A:C, 'Protas (424–441)'!E:E}, 'Protas (424–441)'!E:E>0), {"""","""","""",""""}); IFERROR(FILTER({'Super Cracks (442–467)'!A:C, 'Super Cracks (442–467)'!E:E}, 'Super Cracks (442–467)'!E:E>0), {"""","""","""",""""}); IFERROR(FILT"&"ER({'Cartas Top y Únicas (468–478)'!A:C, 'Cartas Top y Únicas (468–478)'!E:E}, 'Cartas Top y Únicas (468–478)'!E:E>0), {"""","""","""",""""}); IFERROR(FILTER({Estadios!A:C, Estadios!E:E}, Estadios!E:E>0), {"""","""","""",""""}) }, ""select * where Col1 "&"is not null order by Col1 asc"", 0)"),1.0) -> 1 | B1: =IFERROR(__xludf.DUMMYFUNCTION("""COMPUTED_VALUE"""),"ESCUDO") -> ESCUDO | C1: =IFERROR(__xludf.DUMMYFUNCTION("""COMPUTED_VALUE"""),"D. ALAVÉS") -> D. ALAVÉS | D1: =IFERROR(__xludf.DUMMYFUNCTION("""COMPUTED_VALUE"""),1.0) -> 1
A2: =IFERROR(__xludf.DUMMYFUNCTION("""COMPUTED_VALUE"""),4.0) -> 4 | B2: =IFERROR(__xludf.DUMMYFUNCTION("""COMPUTED_VALUE"""),"JONNY") -> JONNY | C2: =IFERROR(__xludf.DUMMYFUNCTION("""COMPUTED_VALUE"""),"D. ALAVÉS") -> D. ALAVÉS | D2: =IFERROR(__xludf.DUMMYFUNCTION("""COMPUTED_VALUE"""),2.0) -> 2
A3: =IFERROR(__xludf.DUMMYFUNCTION("""COMPUTED_VALUE"""),27.0) -> 27 | B3: =IFERROR(__xludf.DUMMYFUNCTION("""COMPUTED_VALUE"""),"RUIZ DE GALARRETA") -> RUIZ DE GALARRETA | C3: =IFERROR(__xludf.DUMMYFUNCTION("""COMPUTED_VALUE"""),"ATHLETIC CLUB") -> ATHLETIC CLUB | D3: =IFERROR(__xludf.DUMMYFUNCTION("""COMPUTED_VALUE"""),1.0) -> 1
A4: =IFERROR(__xludf.DUMMYFUNCTION("""COMPUTED_VALUE"""),34.0) -> 34 | B4: =IFERROR(__xludf.DUMMYFUNCTION("""COMPUTED_VALUE"""),"MAROAN") -> MAROAN | C4: =IFERROR(__xludf.DUMMYFUNCTION("""COMPUTED_VALUE"""),"ATHLETIC CLUB") -> ATHLETIC CLUB | D4: =IFERROR(__xludf.DUMMYFUNCTION("""COMPUTED_VALUE"""),1.0) -> 1
A5: =IFERROR(__xludf.DUMMYFUNCTION("""COMPUTED_VALUE"""),46.0) -> 46 | B5: =IFERROR(__xludf.DUMMYFUNCTION("""COMPUTED_VALUE"""),"BARRIOS") -> BARRIOS | C5: =IFERROR(__xludf.DUMMYFUNCTION("""COMPUTED_VALUE"""),"ATLÉTICO DE MADRID") -> ATLÉTICO DE MADRID | D5: =IFERROR(__xludf.DUMMYFUNCTION("""COMPUTED_VALUE"""),1.0) -> 1
A6: =IFERROR(__xludf.DUMMYFUNCTION("""COMPUTED_VALUE"""),49.0) -> 49 | B6: =IFERROR(__xludf.DUMMYFUNCTION("""COMPUTED_VALUE"""),"ALMADA") -> ALMADA | C6: =IFERROR(__xludf.DUMMYFUNCTION("""COMPUTED_VALUE"""),"ATLÉTICO DE MADRID") -> ATLÉTICO DE MADRID | D6: =IFERROR(__xludf.DUMMYFUNCTION("""COMPUTED_VALUE"""),1.0) -> 1
A7: =IFERROR(__xludf.DUMMYFUNCTION("""COMPUTED_VALUE"""),64.0) -> 64 | B7: =IFERROR(__xludf.DUMMYFUNCTION("""COMPUTED_VALUE"""),"GAVI") -> GAVI | C7: =IFERROR(__xludf.DUMMYFUNCTION("""COMPUTED_VALUE"""),"FC BARCELONA") -> FC BARCELONA | D7: =IFERROR(__xludf.DUMMYFUNCTION("""COMPUTED_VALUE"""),1.0) -> 1
A8: =IFERROR(__xludf.DUMMYFUNCTION("""COMPUTED_VALUE"""),67.0) -> 67 | B8: =IFERROR(__xludf.DUMMYFUNCTION("""COMPUTED_VALUE"""),"DANI OLMO") -> DANI OLMO | C8: =IFERROR(__xludf.DUMMYFUNCTION("""COMPUTED_VALUE"""),"FC BARCELONA") -> FC BARCELONA | D8: =IFERROR(__xludf.DUMMYFUNCTION("""COMPUTED_VALUE"""),1.0) -> 1
A9: =IFERROR(__xludf.DUMMYFUNCTION("""COMPUTED_VALUE"""),76.0) -> 76 | B9: =IFERROR(__xludf.DUMMYFUNCTION("""COMPUTED_VALUE"""),"BELLERÍN") -> BELLERÍN | C9: =IFERROR(__xludf.DUMMYFUNCTION("""COMPUTED_VALUE"""),"REAL BETIS") -> REAL BETIS | D9: =IFERROR(__xludf.DUMMYFUNCTION("""COMPUTED_VALUE"""),1.0) -> 1
A10: =IFERROR(__xludf.DUMMYFUNCTION("""COMPUTED_VALUE"""),81.0) -> 81 | B10: =IFERROR(__xludf.DUMMYFUNCTION("""COMPUTED_VALUE"""),"JUNIOR") -> JUNIOR | C10: =IFERROR(__xludf.DUMMYFUNCTION("""COMPUTED_VALUE"""),"REAL BETIS") -> REAL BETIS | D10: =IFERROR(__xludf.DUMMYFUNCTION("""COMPUTED_VALUE"""),1.0) -> 1
A11: =IFERROR(__xludf.DUMMYFUNCTION("""COMPUTED_VALUE"""),107.0) -> 107 | B11: =IFERROR(__xludf.DUMMYFUNCTION("""COMPUTED_VALUE"""),"BORJA IGLESIAS") -> BORJA IGLESIAS | C11: =IFERROR(__xludf.DUMMYFUNCTION("""COMPUTED_VALUE"""),"RC CELTA") -> RC CELTA | D11: =IFERROR(__xludf.DUMMYFUNCTION("""COMPUTED_VALUE"""),1.0) -> 1
A12: =IFERROR(__xludf.DUMMYFUNCTION("""COMPUTED_VALUE"""),108.0) -> 108 | B12: =IFERROR(__xludf.DUMMYFUNCTION("""COMPUTED_VALUE"""),"JUTGLÀ") -> JUTGLÀ | C12: =IFERROR(__xludf.DUMMYFUNCTION("""COMPUTED_VALUE"""),"RC CELTA") -> RC CELTA | D12: =IFERROR(__xludf.DUMMYFUNCTION("""COMPUTED_VALUE"""),2.0) -> 2
A13: =IFERROR(__xludf.DUMMYFUNCTION("""COMPUTED_VALUE"""),110.0) -> 110 | B13: =IFERROR(__xludf.DUMMYFUNCTION("""COMPUTED_VALUE"""),"IÑAKI PEÑA") -> IÑAKI PEÑA | C13: =IFERROR(__xludf.DUMMYFUNCTION("""COMPUTED_VALUE"""),"ELCHE CF") -> ELCHE CF | D13: =IFERROR(__xludf.DUMMYFUNCTION("""COMPUTED_VALUE"""),2.0) -> 2
A14: =IFERROR(__xludf.DUMMYFUNCTION("""COMPUTED_VALUE"""),121.0) -> 121 | B14: =IFERROR(__xludf.DUMMYFUNCTION("""COMPUTED_VALUE"""),"MARC AGUADO") -> MARC AGUADO | C14: =IFERROR(__xludf.DUMMYFUNCTION("""COMPUTED_VALUE"""),"ELCHE CF") -> ELCHE CF | D14: =IFERROR(__xludf.DUMMYFUNCTION("""COMPUTED_VALUE"""),1.0) -> 1
A15: =IFERROR(__xludf.DUMMYFUNCTION("""COMPUTED_VALUE"""),127.0) -> 127 | B15: =IFERROR(__xludf.DUMMYFUNCTION("""COMPUTED_VALUE"""),"ESCUDO") -> ESCUDO | C15: =IFERROR(__xludf.DUMMYFUNCTION("""COMPUTED_VALUE"""),"RCD ESPANYOL") -> RCD ESPANYOL | D15: =IFERROR(__xludf.DUMMYFUNCTION("""COMPUTED_VALUE"""),1.0) -> 1
A16: =IFERROR(__xludf.DUMMYFUNCTION("""COMPUTED_VALUE"""),130.0) -> 130 | B16: =IFERROR(__xludf.DUMMYFUNCTION("""COMPUTED_VALUE"""),"EL HILALI") -> EL HILALI | C16: =IFERROR(__xludf.DUMMYFUNCTION("""COMPUTED_VALUE"""),"RCD ESPANYOL") -> RCD ESPANYOL | D16: =IFERROR(__xludf.DUMMYFUNCTION("""COMPUTED_VALUE"""),1.0) -> 1
A17: =IFERROR(__xludf.DUMMYFUNCTION("""COMPUTED_VALUE"""),154.0) -> 154 | B17: =IFERROR(__xludf.DUMMYFUNCTION("""COMPUTED_VALUE"""),"DAVINCHI") -> DAVINCHI | C17: =IFERROR(__xludf.DUMMYFUNCTION("""COMPUTED_VALUE"""),"GETAFE CF") -> GETAFE CF | D17: =IFERROR(__xludf.DUMMYFUNCTION("""COMPUTED_VALUE"""),1.0) -> 1
A18: =IFERROR(__xludf.DUMMYFUNCTION("""COMPUTED_VALUE"""),176.0) -> 176 | B18: =IFERROR(__xludf.DUMMYFUNCTION("""COMPUTED_VALUE"""),"JOEL ROCA") -> JOEL ROCA | C18: =IFERROR(__xludf.DUMMYFUNCTION("""COMPUTED_VALUE"""),"GIRONA FC") -> GIRONA FC | D18: =IFERROR(__xludf.DUMMYFUNCTION("""COMPUTED_VALUE"""),1.0) -> 1
A19: =IFERROR(__xludf.DUMMYFUNCTION("""COMPUTED_VALUE"""),180.0) -> 180 | B19: =IFERROR(__xludf.DUMMYFUNCTION("""COMPUTED_VALUE"""),"BRYAN GIL") -> BRYAN GIL | C19: =IFERROR(__xludf.DUMMYFUNCTION("""COMPUTED_VALUE"""),"GIRONA FC") -> GIRONA FC | D19: =IFERROR(__xludf.DUMMYFUNCTION("""COMPUTED_VALUE"""),1.0) -> 1
A20: =IFERROR(__xludf.DUMMYFUNCTION("""COMPUTED_VALUE"""),202.0) -> 202 | B20: =IFERROR(__xludf.DUMMYFUNCTION("""COMPUTED_VALUE"""),"CARVAJAL") -> CARVAJAL | C20: =IFERROR(__xludf.DUMMYFUNCTION("""COMPUTED_VALUE"""),"REAL MADRID") -> REAL MADRID | D20: =IFERROR(__xludf.DUMMYFUNCTION("""COMPUTED_VALUE"""),1.0) -> 1
A21: =IFERROR(__xludf.DUMMYFUNCTION("""COMPUTED_VALUE"""),209.0) -> 209 | B21: =IFERROR(__xludf.DUMMYFUNCTION("""COMPUTED_VALUE"""),"FEDE VALVERDE") -> FEDE VALVERDE | C21: =IFERROR(__xludf.DUMMYFUNCTION("""COMPUTED_VALUE"""),"REAL MADRID") -> REAL MADRID | D21: =IFERROR(__xludf.DUMMYFUNCTION("""COMPUTED_VALUE"""),1.0) -> 1
A22: =IFERROR(__xludf.DUMMYFUNCTION("""COMPUTED_VALUE"""),235.0) -> 235 | B22: =IFERROR(__xludf.DUMMYFUNCTION("""COMPUTED_VALUE"""),"ESCUDO") -> ESCUDO | C22: =IFERROR(__xludf.DUMMYFUNCTION("""COMPUTED_VALUE"""),"CA OSASUNA") -> CA OSASUNA | D22: =IFERROR(__xludf.DUMMYFUNCTION("""COMPUTED_VALUE"""),1.0) -> 1
A23: =IFERROR(__xludf.DUMMYFUNCTION("""COMPUTED_VALUE"""),240.0) -> 240 | B23: =IFERROR(__xludf.DUMMYFUNCTION("""COMPUTED_VALUE"""),"CATENA") -> CATENA | C23: =IFERROR(__xludf.DUMMYFUNCTION("""COMPUTED_VALUE"""),"CA OSASUNA") -> CA OSASUNA | D23: =IFERROR(__xludf.DUMMYFUNCTION("""COMPUTED_VALUE"""),1.0) -> 1
A24: =IFERROR(__xludf.DUMMYFUNCTION("""COMPUTED_VALUE"""),259.0) -> 259 | B24: =IFERROR(__xludf.DUMMYFUNCTION("""COMPUTED_VALUE"""),"DANI CALVO") -> DANI CALVO | C24: =IFERROR(__xludf.DUMMYFUNCTION("""COMPUTED_VALUE"""),"REAL OVIEDO") -> REAL OVIEDO | D24: =IFERROR(__xludf.DUMMYFUNCTION("""COMPUTED_VALUE"""),1.0) -> 1
A25: =IFERROR(__xludf.DUMMYFUNCTION("""COMPUTED_VALUE"""),269.0) -> 269 | B25: =IFERROR(__xludf.DUMMYFUNCTION("""COMPUTED_VALUE"""),"FEDE VIÑAS") -> FEDE VIÑAS | C25: =IFERROR(__xludf.DUMMYFUNCTION("""COMPUTED_VALUE"""),"REAL OVIEDO") -> REAL OVIEDO | D25: =IFERROR(__xludf.DUMMYFUNCTION("""COMPUTED_VALUE"""),1.0) -> 1
A26: =IFERROR(__xludf.DUMMYFUNCTION("""COMPUTED_VALUE"""),272.0) -> 272 | B26: =IFERROR(__xludf.DUMMYFUNCTION("""COMPUTED_VALUE"""),"BATALLA") -> BATALLA | C26: =IFERROR(__xludf.DUMMYFUNCTION("""COMPUTED_VALUE"""),"RAYO VALLECANO") -> RAYO VALLECANO | D26: =IFERROR(__xludf.DUMMYFUNCTION("""COMPUTED_VALUE"""),1.0) -> 1
A27: =IFERROR(__xludf.DUMMYFUNCTION("""COMPUTED_VALUE"""),281.0) -> 281 | B27: =IFERROR(__xludf.DUMMYFUNCTION("""COMPUTED_VALUE"""),"ÓSCAR VALENTÍN") -> ÓSCAR VALENTÍN | C27: =IFERROR(__xludf.DUMMYFUNCTION("""COMPUTED_VALUE"""),"RAYO VALLECANO") -> RAYO VALLECANO | D27: =IFERROR(__xludf.DUMMYFUNCTION("""COMPUTED_VALUE"""),1.0) -> 1
A28: =IFERROR(__xludf.DUMMYFUNCTION("""COMPUTED_VALUE"""),283.0) -> 283 | B28: =IFERROR(__xludf.DUMMYFUNCTION("""COMPUTED_VALUE"""),"PEDRO DÍAZ") -> PEDRO DÍAZ | C28: =IFERROR(__xludf.DUMMYFUNCTION("""COMPUTED_VALUE"""),"RAYO VALLECANO") -> RAYO VALLECANO | D28: =IFERROR(__xludf.DUMMYFUNCTION("""COMPUTED_VALUE"""),1.0) -> 1
A29: =IFERROR(__xludf.DUMMYFUNCTION("""COMPUTED_VALUE"""),292.0) -> 292 | B29: =IFERROR(__xludf.DUMMYFUNCTION("""COMPUTED_VALUE"""),"ARAMBURU") -> ARAMBURU | C29: =IFERROR(__xludf.DUMMYFUNCTION("""COMPUTED_VALUE"""),"REAL SOCIEDAD") -> REAL SOCIEDAD | D29: =IFERROR(__xludf.DUMMYFUNCTION("""COMPUTED_VALUE"""),1.0) -> 1
A30: =IFERROR(__xludf.DUMMYFUNCTION("""COMPUTED_VALUE"""),295.0) -> 295 | B30: =IFERROR(__xludf.DUMMYFUNCTION("""COMPUTED_VALUE"""),"CALETA-CAR") -> CALETA-CAR | C30: =IFERROR(__xludf.DUMMYFUNCTION("""COMPUTED_VALUE"""),"REAL SOCIEDAD") -> REAL SOCIEDAD | D30: =IFERROR(__xludf.DUMMYFUNCTION("""COMPUTED_VALUE"""),1.0) -> 1
A31: =IFERROR(__xludf.DUMMYFUNCTION("""COMPUTED_VALUE"""),309.0) -> 309 | B31: =IFERROR(__xludf.DUMMYFUNCTION("""COMPUTED_VALUE"""),"NYLAND") -> NYLAND | C31: =IFERROR(__xludf.DUMMYFUNCTION("""COMPUTED_VALUE"""),"SEVILLA FC") -> SEVILLA FC | D31: =IFERROR(__xludf.DUMMYFUNCTION("""COMPUTED_VALUE"""),1.0) -> 1
A32: =IFERROR(__xludf.DUMMYFUNCTION("""COMPUTED_VALUE"""),313.0) -> 313 | B32: =IFERROR(__xludf.DUMMYFUNCTION("""COMPUTED_VALUE"""),"KIKE SALAS") -> KIKE SALAS | C32: =IFERROR(__xludf.DUMMYFUNCTION("""COMPUTED_VALUE"""),"SEVILLA FC") -> SEVILLA FC | D32: =IFERROR(__xludf.DUMMYFUNCTION("""COMPUTED_VALUE"""),2.0) -> 2
A33: =IFERROR(__xludf.DUMMYFUNCTION("""COMPUTED_VALUE"""),317.0) -> 317 | B33: =IFERROR(__xludf.DUMMYFUNCTION("""COMPUTED_VALUE"""),"AGOUME") -> AGOUME | C33: =IFERROR(__xludf.DUMMYFUNCTION("""COMPUTED_VALUE"""),"SEVILLA FC") -> SEVILLA FC | D33: =IFERROR(__xludf.DUMMYFUNCTION("""COMPUTED_VALUE"""),1.0) -> 1
A34: =IFERROR(__xludf.DUMMYFUNCTION("""COMPUTED_VALUE"""),323.0) -> 323 | B34: =IFERROR(__xludf.DUMMYFUNCTION("""COMPUTED_VALUE"""),"AKOR ADAMS") -> AKOR ADAMS | C34: =IFERROR(__xludf.DUMMYFUNCTION("""COMPUTED_VALUE"""),"SEVILLA FC") -> SEVILLA FC | D34: =IFERROR(__xludf.DUMMYFUNCTION("""COMPUTED_VALUE"""),1.0) -> 1
A35: =IFERROR(__xludf.DUMMYFUNCTION("""COMPUTED_VALUE"""),330.0) -> 330 | B35: =IFERROR(__xludf.DUMMYFUNCTION("""COMPUTED_VALUE"""),"TÁRREGA") -> TÁRREGA | C35: =IFERROR(__xludf.DUMMYFUNCTION("""COMPUTED_VALUE"""),"VALENCIA CF") -> VALENCIA CF | D35: =IFERROR(__xludf.DUMMYFUNCTION("""COMPUTED_VALUE"""),1.0) -> 1
A36: =IFERROR(__xludf.DUMMYFUNCTION("""COMPUTED_VALUE"""),333.0) -> 333 | B36: =IFERROR(__xludf.DUMMYFUNCTION("""COMPUTED_VALUE"""),"GAYÀ") -> GAYÀ | C36: =IFERROR(__xludf.DUMMYFUNCTION("""COMPUTED_VALUE"""),"VALENCIA CF") -> VALENCIA CF | D36: =IFERROR(__xludf.DUMMYFUNCTION("""COMPUTED_VALUE"""),1.0) -> 1
A37: =IFERROR(__xludf.DUMMYFUNCTION("""COMPUTED_VALUE"""),338.0) -> 338 | B37: =IFERROR(__xludf.DUMMYFUNCTION("""COMPUTED_VALUE"""),"LUIS RIOJA") -> LUIS RIOJA | C37: =IFERROR(__xludf.DUMMYFUNCTION("""COMPUTED_VALUE"""),"VALENCIA CF") -> VALENCIA CF | D37: =IFERROR(__xludf.DUMMYFUNCTION("""COMPUTED_VALUE"""),1.0) -> 1
A38: =IFERROR(__xludf.DUMMYFUNCTION("""COMPUTED_VALUE"""),343.0) -> 343 | B38: =IFERROR(__xludf.DUMMYFUNCTION("""COMPUTED_VALUE"""),"ESCUDO") -> ESCUDO | C38: =IFERROR(__xludf.DUMMYFUNCTION("""COMPUTED_VALUE"""),"VILLARREAL CF") -> VILLARREAL CF | D38: =IFERROR(__xludf.DUMMYFUNCTION("""COMPUTED_VALUE"""),1.0) -> 1
A39: =IFERROR(__xludf.DUMMYFUNCTION("""COMPUTED_VALUE"""),343.0) -> 343 | B39: =IFERROR(__xludf.DUMMYFUNCTION("""COMPUTED_VALUE"""),"ESTADIO") -> ESTADIO | C39: =IFERROR(__xludf.DUMMYFUNCTION("""COMPUTED_VALUE"""),"VILLARREAL CF") -> VILLARREAL CF | D39: =IFERROR(__xludf.DUMMYFUNCTION("""COMPUTED_VALUE"""),1.0) -> 1
A40: =IFERROR(__xludf.DUMMYFUNCTION("""COMPUTED_VALUE"""),352.0) -> 352 | B40: =IFERROR(__xludf.DUMMYFUNCTION("""COMPUTED_VALUE"""),"PAPE GUEYE") -> PAPE GUEYE | C40: =IFERROR(__xludf.DUMMYFUNCTION("""COMPUTED_VALUE"""),"VILLARREAL CF") -> VILLARREAL CF | D40: =IFERROR(__xludf.DUMMYFUNCTION("""COMPUTED_VALUE"""),2.0) -> 2
...

Sheet REGULARES
A1: 1 | B1: ESCUDO | C1: D. ALAVÉS | D1: SI | E1: 1
A2: 2 | B2: SIVERA | C2: D. ALAVÉS
A3: 3 | B3: RAÚL FERNÁNDEZ | C3: D. ALAVÉS | D3: SI
A4: 4 | B4: JONNY | C4: D. ALAVÉS | D4: SI | E4: 2
A5: 5 | B5: TENAGLIA | C5: D. ALAVÉS
A6: 6 | B6: PACHECO | C6: D. ALAVÉS | D6: SI
A7: 7 | B7: PARADA | C7: D. ALAVÉS | D7: SI
A8: 8 | B8: MOUSSA DIARRA | C8: D. ALAVÉS
A9: 9 | B9: BLANCO | C9: D. ALAVÉS | D9: SI
A10: 10 | B10: GUEVARA | C10: D. ALAVÉS | D10: SI
A11: 11 | B11: GURIDI | C11: D. ALAVÉS
A12: 12 | B12: ALEÑÁ | C12: D. ALAVÉS
A13: 13 | B13: PABLO IBÁÑEZ | C13: D. ALAVÉS
A14: 14 | B14: DENIS SUÁREZ | C14: D. ALAVÉS
A15: 15 | B15: CARLOS VICENTE | C15: D. ALAVÉS | D15: SI
A16: 16 | B16: TONI MARTÍNEZ | C16: D. ALAVÉS
A17: 17 | B17: BOYÉ | C17: D. ALAVÉS | D17: SI
A18: 18 | B18: MARIANO | C18: D. ALAVÉS | D18: SI
A19: 19 | B19: ESCUDO | C19: ATHLETIC CLUB
A20: 20 | B20: UNAI SIMÓN | C20: ATHLETIC CLUB
A21: 21 | B21: PADILLA | C21: ATHLETIC CLUB | D21: SI
A22: 22 | B22: ARESO | C22: ATHLETIC CLUB | D22: SI
A23: 23 | B23: VIVIAN | C23: ATHLETIC CLUB | D23: SI
A24: 24 | B24: PAREDES | C24: ATHLETIC CLUB
A25: 25 | B25: LAPORTE | C25: ATHLETIC CLUB
A26: 26 | B26: YURI | C26: ATHLETIC CLUB
A27: 27 | B27: RUIZ DE GALARRETA | C27: ATHLETIC CLUB | D27: SI | E27: 1
A28: 28 | B28: JAUREGIZAR | C28: ATHLETIC CLUB
A29: 29 | B29: VESGA | C29: ATHLETIC CLUB
A30: 30 | B30: UNAI GÓMEZ | C30: ATHLETIC CLUB
A31: 31 | B31: SANCET | C31: ATHLETIC CLUB | D31: SI
A32: 32 | B32: BERENGUER | C32: ATHLETIC CLUB
A33: 33 | B33: WILLIAMS | C33: ATHLETIC CLUB | D33: SI
A34: 34 | B34: MAROAN | C34: ATHLETIC CLUB | D34: SI | E34: 1
A35: 35 | B35: GURUZETA | C35: ATHLETIC CLUB
A36: 36 | B36: NICO WILLIAMS | C36: ATHLETIC CLUB
A37: 37 | B37: ESCUDO | C37: ATLÉTICO DE MADRID
A38: 38 | B38: OBLAK | C38: ATLÉTICO DE MADRID
A39: 39 | B39: MUSSO | C39: ATLÉTICO DE MADRID | D39: SI
A40: 40 | B40: MARCOS LLORENTE | C40: ATLÉTICO DE MADRID | D40: SI
...

Sheet Estadios
A1: 1 | B1: ESTADIO | C1: D. ALAVÉS | D1: SI
A2: 19 | B2: ESTADIO | C2: ATHLETIC CLUB | D2: SI
A3: 37 | B3: ESTADIO | C3: ATLÉTICO DE MADRID | D3: SI
A4: 55 | B4: ESTADIO | C4: FC BARCELONA | D4: SI
A5: 73 | B5: ESTADIO | C5: REAL BETIS | D5: SI
A6: 91 | B6: ESTADIO | C6: RC CELTA
A7: 109 | B7: ESTADIO | C7: ELCHE CF | D7: SI
A8: 127 | B8: ESTADIO | C8: RCD ESPANYOL | D8: SI
A9: 145 | B9: ESTADIO | C9: GETAFE CF | D9: SI
A10: 163 | B10: ESTADIO | C10: GIRONA FC
A11: 181 | B11: ESTADIO | C11: LEVANTE UD
A12: 199 | B12: ESTADIO | C12: REAL MADRID | D12: SI
A13: 217 | B13: ESTADIO | C13: RCD MALLORCA
A14: 235 | B14: ESTADIO | C14: CA OSASUNA
A15: 253 | B15: ESTADIO | C15: REAL OVIEDO | D15: SI
A16: 271 | B16: ESTADIO | C16: RAYO VALLECANO
A17: 289 | B17: ESTADIO | C17: REAL SOCIEDAD | D17: SI
A18: 307 | B18: ESTADIO | C18: SEVILLA FC | D18: SI
A19: 325 | B19: ESTADIO | C19: VALENCIA CF | D19: SI
A20: 343 | B20: ESTADIO | C20: VILLARREAL CF | D20: SI | E20: 1

Sheet ¡VAMOS! (361–380)
A1: 361 | B1: D. ALAVÉS | C1: ¡VAMOS!
A2: 362 | B2: ATHLETIC CLUB | C2: ¡VAMOS! | D2: SI
A3: 363 | B3: ATLÉTICO DE MADRID | C3: ¡VAMOS! | D3: SI
A4: 364 | B4: FC BARCELONA | C4: ¡VAMOS!
A5: 365 | B5: REAL BETIS | C5: ¡VAMOS!
A6: 366 | B6: RC CELTA | C6: ¡VAMOS!
A7: 367 | B7: ELCHE CF | C7: ¡VAMOS!
A8: 368 | B8: RCD ESPANYOL | C8: ¡VAMOS! | D8: SI
A9: 369 | B9: GETAFE CF | C9: ¡VAMOS! | D9: SI | E9: 1
A10: 370 | B10: GIRONA FC | C10: ¡VAMOS! | D10: SI
A11: 371 | B11: LEVANTE UD | C11: ¡VAMOS! | D11: SI
A12: 372 | B12: REAL MADRID | C12: ¡VAMOS!
A13: 373 | B13: RCD MALLORCA | C13: ¡VAMOS!
A14: 374 | B14: CA OSASUNA | C14: ¡VAMOS! | D14: SI
A15: 375 | B15: REAL OVIEDO | C15: ¡VAMOS!
A16: 376 | B16: RAYO VALLECANO | C16: ¡VAMOS!
A17: 377 | B17: REAL SOCIEDAD | C17: ¡VAMOS!
A18: 378 | B18: SEVILLA FC | C18: ¡VAMOS!
A19: 379 | B19: VALENCIA CF | C19: ¡VAMOS! | D19: SI
A20: 380 | B20: VILLARREAL CF | C20: ¡VAMOS!

Sheet Guantes de Oro (381–387)
A1: 381 | B1: SIVERA | C1: D. ALAVÉS | D1: SI
A2: 382 | B2: JOAN GARCÍA | C2: FC BARCELONA | D2: SI
A3: 383 | B3: DAVID SORIA | C3: GETAFE CF
A4: 384 | B4: SERGIO HERRERA | C4: CA OSASUNA
A5: 385 | B5: BATALLA | C5: RAYO VALLECANO
A6: 386 | B6: REMIRO | C6: REAL SOCIEDAD
A7: 387 | B7: AGIRREZABALA | C7: VALENCIA CF

Sheet Kryptonita (388–396)
A1: 388 | B1: LAPORTE | C1: ATHLETIC CLUB
A2: 389 | B2: VIVIAN | C2: ATHLETIC CLUB
A3: 390 | B3: LE NORMAND | C3: ATLÉTICO DE MADRID
A4: 391 | B4: AFFENGRUBER | C4: ELCHE CF | D4: SI
A5: 392 | B5: CABRERA | C5: RCD ESPANYOL | D5: SI | E5: 2
A6: 393 | B6: MILITAO | C6: REAL MADRID
A7: 394 | B7: LEJEUNE | C7: RAYO VALLECANO
A8: 395 | B8: TÁRREGA | C8: VALENCIA CF
A9: 396 | B9: MOURIÑO | C9: VILLARREAL CF | D9: SI

Sheet Diamantes (397–414)
A1: 397 | B1: REGO | C1: ATHLETIC CLUB
A2: 398 | B2: DRO | C2: FC BARCELONA | D2: SI
A3: 399 | B3: VALENTÍN GÓMEZ | C3: REAL BETIS
A4: 400 | B4: PABLO GARCÍA | C4: REAL BETIS | D4: SI
A5: 401 | B5: RODRI MENDOZA | C5: ELCHE CF
A6: 402 | B6: RIEDEL | C6: RCD ESPANYOL | D6: SI
A7: 403 | B7: DAVINCHI | C7: GETAFE CF | D7: SI
A8: 404 | B8: LISO | C8: GETAFE CF | D8: SI | E8: 1
A9: 405 | B9: VITOR REIS | C9: GIRONA FC | D9: SI
A10: 406 | B10: JOEL ROCA | C10: GIRONA FC | D10: SI
A11: 407 | B11: CARLOS ÁLVAREZ | C11: LEVANTE UD | D11: SI
A12: 408 | B12: ETTA EYONG | C12: LEVANTE UD | D12: SI
A13: 409 | B13: FRAN GONZÁLEZ | C13: REAL MADRID | D13: SI | E13: 1
A14: 410 | B14: GONZALO | C14: REAL MADRID
A15: 411 | B15: JAN VIRGILI | C15: RCD MALLORCA
A16: 412 | B16: MATEO JOSEPH | C16: RCD MALLORCA
A17: 413 | B17: VÍCTOR MUÑOZ | C17: CA OSASUNA | D17: SI
A18: 414 | B18: RENATO VEIGA | C18: VILLARREAL CF | D18: si | E18: 1

Sheet Influencers (415–423)
A1: 415 | B1: BARRIOS | C1: ATLÉTICO DE MADRID | D1: SI | E1: 1
A2: 416 | B2: SOTELO | C2: RC CELTA | D2: SI | E2: 1
A3: 417 | B3: FEBAS | C3: ELCHE CF
A4: 418 | B4: EDU EXPÓSITO | C4: RCD ESPANYOL
A5: 419 | B5: MILLA | C5: GETAFE CF | D5: SI
A6: 420 | B6: DARDER | C6: RCD MALLORCA
A7: 421 | B7: AIMAR OROZ | C7: CA OSASUNA | D7: SI
A8: 422 | B8: CAZORLA | C8: REAL OVIEDO | D8: SI
A9: 423 | B9: UNAI LÓPEZ | C9: RAYO VALLECANO

Sheet Protas (424–441)
A1: 424 | B1: TENAGLIA | C1: D. ALAVÉS
A2: 425 | B2: CARLOS VICENTE | C2: D. ALAVÉS | D2: SI
A3: 426 | B3: ERIC GARCÍA | C3: FC BARCELONA | D3: SI
A4: 427 | B4: CUCHO HERNÁNDEZ | C4: REAL BETIS | D4: SI
A5: 428 | B5: BORJA IGLESIAS | C5: RC CELTA
A6: 429 | B6: DOLAN | C6: RCD ESPANYOL
A7: 430 | B7: VANAT | C7: GIRONA FC
A8: 431 | B8: MANU SÁNCHEZ | C8: LEVANTE UD | D8: SI
A9: 432 | B9: TCHOUAMÉNI | C9: REAL MADRID
A10: 433 | B10: LEO ROMÁN | C10: RCD MALLORCA
A11: 434 | B11: AARON ESCANDELL | C11: REAL OVIEDO | D11: SI
A12: 435 | B12: HASSAN | C12: REAL OVIEDO
A13: 436 | B13: CARLOS SOLER | C13: REAL SOCIEDAD | D13: SI
A14: 437 | B14: GORROTXATEGI | C14: REAL SOCIEDAD
A15: 438 | B15: BATISTA MENDY | C15: SEVILLA FC
A16: 439 | B16: ALEXIS SÁNCHEZ | C16: SEVILLA FC | D16: SI
A17: 440 | B17: DANJUMA | C17: VALENCIA CF | D17: SI
A18: 441 | B18: BUCHANAN | C18: VILLARREAL CF

Sheet Cartas Top y Únicas (468–478)
A1: 468 | B1: CARD CHAMPIONS | C1: ÚNICA
A2: 469 | B2: NICO WILLIAMS | C2: BALÓN DE ORO (ATHLETIC) | D2: SI | E2: 2
A3: 470 | B3: JULIÁN ÁLVAREZ | C3: BALÓN DE ORO (ATLÉTICO)
A4: 471 | B4: PEDRI | C4: BALÓN DE ORO (BARÇA)
A5: 472 | B5: LAMINE YAMAL | C5: BALÓN DE ORO (BARÇA)
A6: 473 | B6: VINÍCIUS | C6: BALÓN DE ORO (REAL MADRID)
A7: 474 | B7: MBAPPÉ | C7: BALÓN DE ORO (REAL MADRID) | D7: SI
A8: 475 | B8: BALÓN DE ORO EXCELLENCE | C8: ÚNICA
A9: 476 | B9: CARD ATÓMICA | C9: ÚNICA
A10: 477 | B10: CARD INVENCIBLE | C10: ÚNICA | D10: SI
A11: 478 | B11: CAMPEÓN CARD | C11: ÚNICA

Sheet Super Cracks (442–467)
A1: 442 | B1: UNAI SIMÓN | C1: ATHLETIC CLUB
A2: 443 | B2: JAUREGIZAR | C2: ATHLETIC CLUB
A3: 444 | B3: OBLAK | C3: ATLÉTICO DE MADRID | D3: SI
A4: 445 | B4: MARCOS LLORENTE | C4: ATLÉTICO DE MADRID
A5: 446 | B5: ÁLEX BAENA | C5: ATLÉTICO DE MADRID
A6: 447 | B6: ALMADA | C6: ATLÉTICO DE MADRID | D6: SI | E6: 1
A7: 448 | B7: GRIEZMANN | C7: ATLÉTICO DE MADRID | D7: SI
A8: 449 | B8: KOUNDÉ | C8: FC BARCELONA | D8: SI
A9: 450 | B9: BALDE | C9: FC BARCELONA
A10: 451 | B10: RAPHINHA | C10: FC BARCELONA
A11: 452 | B11: LEWANDOWSKI | C11: FC BARCELONA | D11: SI | E11: 1
A12: 453 | B12: RASHFORD | C12: FC BARCELONA
A13: 454 | B13: ISCO | C13: REAL BETIS
A14: 455 | B14: LO CELSO | C14: REAL BETIS | D14: SI
A15: 456 | B15: ANTONY | C15: REAL BETIS | D15: SI
A16: 457 | B16: COURTOIS | C16: REAL MADRID
A17: 458 | B17: CARRERAS | C17: REAL MADRID | D17: SI
A18: 459 | B18: FEDE VALVERDE | C18: REAL MADRID
A19: 460 | B19: MASTANTUONO | C19: REAL MADRID
A20: 461 | B20: BUDIMIR | C20: CA OSASUNA | D20: SI
A21: 462 | B21: ISI | C21: RAYO VALLECANO | D21: SI
A22: 463 | B22: KUBO | C22: REAL SOCIEDAD
A23: 464 | B23: VARGAS | C23: SEVILLA FC
A24: 465 | B24: JAVI GUERRA | C24: VALENCIA CF | D24: SI | E24: 1
A25: 466 | B25: MOLEIRO | C25: VILLARREAL CF
A26: 467 | B26: PÉPÉ | C26: VILLARREAL CF | D26: SI
